Workbook

Sheet Work Log
A1: CSIS 4495 - Applied Research Project
A2: Work Log - Desmond Chua (300369803)
A3: BC Personal Health Management Platform
A5: Date | B5: Sprint | C5: Duration | D5: Hours | E5: Category | F5: Task ID | G5: Description of Work Done
A6: 2026-01-09 | B6: 0 | C6: 2 hr | D6: 2 | E6: 0: Environment Setup | G6: Attended CSIS 4495 class; reviewed project requirements; brainstormed initial ideas based on Richmond Hospital experience
A7: 2026-01-09 | B7: 0 | C7: 1.5 hr | D7: 1.5 | E7: 0: Environment Setup | G7: Researched BC healthcare navigation tools; identified gap in existing solutions
A8: 2026-01-15 | B8: 0 | C8: 2 hr | D8: 2 | E8: Learning & Research | G8: Drafted initial chatbot concept; researched CTAS triage guidelines
A9: 2026-01-16 | B9: 0 | C9: 1 hr | D9: 1 | E9: 0: Environment Setup | G9: Meeting #1 with instructor; received feedback to broaden scope; began expanding to multi-feature platform
A10: 2026-01-17 | B10: 0 | C10: 2.5 hr | D10: 2.5 | E10: Learning & Research | G10: Researched OpenAI API documentation; explored integration options
A11: 2026-01-18 | B11: 0 | C11: 2 hr | D11: 2 | E11: 0: Environment Setup | G11: Meeting #2 with instructor (virtual); Option 1 approved; received guidance on focus areas
A12: 2026-01-19 | B12: 0 | C12: 3 hr | D12: 3 | E12: Learning & Research | G12: Designed hybrid classification approach; researched Kaggle symptom datasets
A13: 2026-01-20 | B13: 0 | C13: 2.5 hr | D13: 2.5 | E13: 0: Environment Setup | G13: Created GitHub repository; set up project structure
A14: 2026-01-21 | B14: 0 | C14: 3 hr | D14: 3 | E14: Learning & Research | G14: Researched ML analytics techniques for dashboards; planned Power BI integration
A15: 2026-01-22 | B15: 0 | C15: 2.5 hr | D15: 2.5 | E15: Learning & Research | G15: Explored synthetic data generation approaches; documented data strategy
A16: 2026-01-23 | B16: 0 | C16: 3 hr | D16: 3 | E16: 6: Documentation + Submission | G16: Drafted proposal introduction and literature review sections
A17: 2026-01-24 | B17: 0 | C17: 3.5 hr | D17: 3.5 | E17: 6: Documentation + Submission | G17: Completed methodology section; created technical architecture diagram
A18: 2026-01-30 | B18: 0 | C18: 15 min | D18: 0.25 | E18: 0: Environment Setup | F18: 0.1 | G18: Install Python 3.13+ and verify installation
A19: 2026-01-30 | B19: 0 | C19: 15 min | D19: 0.25 | E19: 0: Environment Setup | F19: 0.2 | G19: Install Visual Studio Code with Claude Code extension
A20: 2026-01-30 | B20: 0 | C20: 15 min | D20: 0.25 | E20: 0: Environment Setup | F20: 0.3 | G20: Create GitHub repo (W26_4495_S2_DesmondC); set up folder structure; add instructor as collaborator
A21: 2026-01-30 | B21: 0 | C21: 15 min | D21: 0.25 | E21: 0: Environment Setup | F21: 0.4a | G21: Create OpenAI account; add $5 API credit
A22: 2026-01-30 | B22: 0 | C22: 5 min | D22: 0.1 | E22: 0: Environment Setup | F22: 0.4b | G22: Create OpenAI API key (BC-Health-Platform)
A23: 2026-01-30 | B23: 0 | C23: 1 hr | D23: 1 | E23: 0: Environment Setup | G23: Attended CSIS 4495 Lesson 4 class; individual check-in with instructor; received feedback on project approach
A24: 2026-01-30 | B24: 0 | C24: 10 min | D24: 0.17 | E24: 0: Environment Setup | F24: 0.5 | G24: Created Streamlit Cloud account; connected with GitHub for deployment
A25: 2026-01-30 | B25: 0 | C25: 5 min | D25: 0.08 | E25: 0: Environment Setup | F25: 0.6 | G25: Created Python virtual environment (venv) for isolated project dependencies
A26: 2026-01-30 | B26: 0 | C26: 15 min | D26: 0.25 | E26: 0: Environment Setup | F26: 0.7 | G26: Installed packages: streamlit, openai, pandas, scikit-learn, plotly, folium, python-dotenv, numpy, nltk, sqlalchemy, spacy
A27: 2026-01-30 | B27: 0 | C27: 5 min | D27: 0.08 | E27: 0: Environment Setup | F27: 0.8 | G27: Ran 'streamlit hello' to verify Streamlit installation; demo app loaded successfully at localhost:8501
A28: 2026-01-30 | B28: 0 | C28: 10 min | D28: 0.17 | E28: 0: Environment Setup | F28: 0.9 | G28: Created requirements.txt using pip freeze; removed spacy model reference for clean deployment
A29: 2026-01-31 | B29: 1 | C29: 25 min | D29: 0.42 | E29: Learning & Research | F29: L2 | G29: Udemy Streamlit ML Deployment - Lesson 2: Installation and Setup (virtual environments, Python 3.8-3.12, streamlit hello)
A30: 2026-01-31 | B30: 1 | C30: 35 min | D30: 0.58 | E30: Learning & Research | F30: L3 | G30: Udemy Streamlit ML Deployment - Lesson 3: Overview of Streamlit (data flow concept, caching preview, key features)
A31: 2026-01-31 | B31: 1 | C31: 30 min | D31: 0.5 | E31: Learning & Research | F31: L4 | G31: Udemy Streamlit ML Deployment - Lesson 4: Creating Basic Streamlit App (main.py, st.text, auto-reload workflow)
A32: 2026-02-01 | B32: 1 | C32: 15 min | D32: 0.25 | E32: Learning & Research | F32: L5 | G32: Udemy Streamlit ML Deployment - Lesson 5: Text Elements (st.title, st.header, st.markdown, st.code, st.latex)
A33: 2026-02-01 | B33: 1 | C33: 20 min | D33: 0.33 | E33: Learning & Research | F33: L6 | G33: Udemy Streamlit ML Deployment - Lesson 6: Data Display Elements (st.dataframe, st.table, st.metric for KPIs)
A34: 2026-02-01 | B34: 1 | C34: 20 min | D34: 0.33 | E34: Learning & Research | F34: L7 | G34: Udemy Streamlit ML Deployment - Lesson 7: Charting Elements (st.line_chart, st.bar_chart, st.area_chart, st.map)
A35: 2026-02-01 | B35: 1 | C35: 25 min | D35: 0.42 | E35: Learning & Research | F35: L8-9 | G35: Udemy Streamlit ML Deployment - Lessons 8-9: Input Widgets (st.button, st.checkbox, st.radio, st.selectbox, st.slider)
... A38: 2026-02-01 | B38: 1 | C38: 40 min | D38: 0.67 | E38: Learning & Research | F38: L12-13 | G38: Udemy Streamlit ML Deployment - Lessons 12-13: Capstone (Canada unemployment dashboard with forms, tabs, metrics, matplotlib)
A39: 2026-02-01 | B39: Sprint 1 | C39: 20 min | D39: 0.33 | E39: 1A: UI Mockups | F39: 1A.1 | G39: Create Mockup 1a - Login page design using UX Pilot
A40: 2026-02-01 | B40: Sprint 1 | C40: 20 min | D40: 0.33 | E40: 1A: UI Mockups | F40: 1A.2 | G40: Create Mockup 1b - Register page with health profile using UX Pilot
A41: 2026-02-01 | B41: Sprint 1 | C41: 20 min | D41: 0.33 | E41: 1A: UI Mockups | F41: 1A.3 | G41: Create Mockup 2a - Home Dashboard design using UX Pilot
A42: 2026-02-01 | B42: Sprint 1 | C42: 20 min | D42: 0.33 | E42: 1A: UI Mockups | F42: 1A.4 | G42: Create Mockup 2b - Facility Finder page design using UX Pilot
A43: 2026-02-01 | B43: Sprint 1 | C43: 20 min | D43: 0.33 | E43: 1A: UI Mockups | F43: 1A.5 | G43: Create Mockup 2c - Health Library page design using UX Pilot
...

Sheet Dashboard
A1: PROJECT PROGRESS DASHBOARD
A3: SPRINT PROGRESS SUMMARY
A4: Sprint | B4: Phase Name | C4: Target Hours | D4: Actual Hours | E4: % Complete
A5: 0 | B5: Environment Setup | C5: 5 | D5: =B45 -> 11.85 | E5: =IF(C5=0,0,MIN(D5/C5,1)) -> 1
A6: 1 | B6: Basic App Structure | C6: 15 | D6: =SUM(B46:B50) -> 14.26 | E6: =IF(C6=0,0,MIN(D6/C6,1)) -> 0.95066667
A7: 2 | B7: Symptom Chatbot | C7: 25 | D7: =SUM(B51:B54) -> 0 | E7: =IF(C7=0,0,MIN(D7/C7,1)) -> 0
A8: 3 | B8: Features 3A-3D | C8: 20 | D8: =SUM(B55:B58) -> 0 | E8: =IF(C8=0,0,MIN(D8/C8,1)) -> 0
A9: 4 | B9: System Analytics | C9: 20 | D9: =SUM(B59:B60) -> 0 | E9: =IF(C9=0,0,MIN(D9/C9,1)) -> 0
A10: 5 | B10: Deployment & Testing | C10: 15 | D10: =SUM(B61:B62) -> 0 | E10: =IF(C10=0,0,MIN(D10/C10,1)) -> 0
A11: 6 | B11: Documentation + Submission | C11: 18 | D11: =SUM(B63) -> 6.5 | E11: =IF(C11=0,0,MIN(D11/C11,1)) -> 0.36111111
A12: TOTAL | C12: =SUM(C5:C11) -> 118 | D12: =SUM(D5:D11) -> 32.61 | E12: =IF(C12=0,0,D12/C12) -> 0.27635593
A14: GANTT CHART - PROJECT TIMELINE
A15: Phase | B15: Week 1 | C15: Week 2 | D15: Week 3 | E15: Week 4 | F15: Week 5 | G15: Week 6 | H15: Week 7 | I15: Week 8 | J15: Week 9 | K15: Week 10 | L15: Week 11 | M15: Week 12 | N15: Week 13
B16: Jan 27 | C16: Feb 3 | D16: Feb 10 | E16: Feb 17 | F16: Feb 24 | G16: Mar 3 | H16: Mar 10 | I16: Mar 17 | J16: Mar 24 | K16: Mar 31 | L16: Apr 7 | M16: Apr 14 | N16: Apr 21
A17: Sprint 0: Environment Setup
A18: Sprint 1: Basic App Structure
A19: 1A: UI Mockups
A20: 1B: Project Structure
A21: 1C: Database Setup
A22: 1D: Authentication Feature
A23: 1E: Basic Navigation
A24: Sprint 2: Symptom Chatbot
A25: 2A: Open AI Integration
A26: 2B: Safety Layer - CTAS Rules
A27: 2C: ML Model Training
A28: 2D: Chatbot UI + Integration
... A34: Sprint 4: System Analytics
A35: 4A: System Analytics Data | F35: ◆
A36: 4B: System Analytics Dashboard | N36: ◆
A37: Sprint 5: Deployment & Testing
A38: 5A: Deployment
A39: 5B: Testing
A40: Sprint 6: Documentation
A42: Category | B42: Hours
A43: HOURS BY CATEGORY
A44: Category | B44: Hours
A45: 0: Environment Setup | B45: =SUMIF('Work Log'!E:E,"0: Environment Setup",'Work Log'!D:D) -> 11.85
A46: 1A: UI Mockups | B46: =SUMIF('Work Log'!E:E,"1A: UI Mockups",'Work Log'!D:D) -> 2.81
A47: 1B: Project Structure | B47: =SUMIF('Work Log'!E:E,"1B: Project Structure",'Work Log'!D:D) -> 0.67
A48: 1C: Database Setup | B48: =SUMIF('Work Log'!E:E,"1C: Database Setup",'Work Log'!D:D) -> 3.18
...

Sheet Categories
A1: Category Reference
A3: Category | B3: Sprint | C3: Description
A4: 0: Environment Setup | B4: 0 | C4: Python, VS Code, GitHub, OpenAI API, Streamlit Cloud setup
A5: 1A: UI Mockups | B5: 1 | C5: Create UI mockups for all pages using UX Pilot
A6: 1B: Project Structure | B6: 1 | C6: Create folder structure, config.toml, placeholder files
A7: 1C: Database Setup | B7: 1 | C7: SQLite database, users/assessments tables, CRUD functions
A8: 1D: Authentication Feature | B8: 1 | C8: Login, register, logout, session management with bcrypt
A9: 1E: Basic Navigation | B9: 1 | C9: Multi-page navigation, sidebar, page routing
A10: 2A: Open AI Integration | B10: 2 | C10: OpenAI API setup, symptom extraction prompts
A11: 2B: Safety Layer - CTAS Rules | B11: 2 | C11: Rule-based critical symptom detection (CTAS guidelines)
A12: 2C: ML Model Training | B12: 2 | C12: Kaggle data, Random Forest training, model.pkl
A13: 2D: Chatbot UI + Integration | B13: 2 | C13: Chat interface, session state, urgency display, integration
A14: 3A: Home Dashboard | B14: 3 | C14: Home page with welcome message, quick stats, navigation cards
A15: 3B: My Dashboard - Personal Analytics | B15: 3
A16: 3C: Facility Finder | B16: 3 | C16: BC facilities data, Folium map, filters by region/type
A17: 3D: Health Education Library | B17: 3 | C17: Health topics JSON, search, topic cards, resources
A18: 4A: System Analytics Data | B18: 4 | C18: Generate 5000 synthetic records, seasonal patterns
A19: 4B: System Analytics Dashboard | B19: 4 | C19: K-Means clustering, anomaly detection, forecasting
A20: 5A: Deployment | B20: 5 | C20: Streamlit Cloud deployment, secrets config, live testing
A21: 5B: Testing | B21: 5 | C21: Test scenarios, user feedback, edge cases, disclaimers
A22: 6: Documentation + Submission | B22: 6 | C22: Final report, demo video, presentation, submission
A23: Learning & Research | B23: - | C23: Udemy courses, tutorials, documentation, self-study
A24: Proof of Concept | B24: - | C24: Code experiments, feature demos, testing feasibility
